-------------------------------------------------------------------
AsyncVoid
-------------------------------------------------------------------
    0 [1] Main: Start    
    2 [1] AsyncVoid: Starting...
   11 [1] Main: Press any key...
 1012 [5] AsyncVoid: Finished and throwing...
 1134 [5] OnAppDomainUnhandled: AppDomain.Unhandled exception: System.Exception: _boom: AsyncVoid_
   at AsyncExamples.AsyncVoid() in C:\vsprojects\AsyncExamples\AsyncExamples.cs:line 11
   at System.Threading.ExecutionContext.RunInternal(ExecutionContext executionContext, ContextCallback callback, Object state)
--- End of stack trace from previous location where exception was thrown ---
   at System.Threading.ThreadPoolWorkQueue.Dispatch()
Unhandled Exception: System.Exception: _boom: AsyncVoid_
   at AsyncExamples.AsyncVoid() in C:\vsprojects\AsyncExamples\AsyncExamples.cs:line 11
   at System.Threading.ExecutionContext.RunInternal(ExecutionContext executionContext, ContextCallback callback, Object state)
--- End of stack trace from previous location where exception was thrown ---
   at System.Threading.ThreadPoolWorkQueue.Dispatch()
-------------------------------------------------------------------
AsyncExamples.AsyncTask();
-------------------------------------------------------------------
    0 [1] Main: Start
    4 [1] AsyncTask: Starting...
   31 [1] Main: Press any key...
 1034 [5] AsyncTask: Finished and throwing...
 5015 [3] ContinuousGc: Executing full GC...
10017 [3] ContinuousGc: Executing full GC...
-------------------------------------------------------------------
AsyncExamples.AsyncTask().GetAwaiter().GetResult();
-------------------------------------------------------------------
    0 [1] Main: Start
    1 [1] AsyncTask: Starting...
 1015 [5] AsyncTask: Finished and throwing...
System.Exception: _boom: AsyncTask_
   at AsyncExamples.AsyncTask() in C:\vsprojects\AsyncExamples\AsyncExamples.cs:line 19
   at AsyncExamples.Program.Main(String[] args) in C:\vsprojects\AsyncExamples\Program.cs:line 22
 1055 [1] Main: Done!
-------------------------------------------------------------------
AsyncExamples.AsyncTask().InAsyncSafe();
-------------------------------------------------------------------
	0 [1] Main: Start
    1 [1] AsyncTask: Starting...
   13 [1] Main: Press any key...
 1013 [5] AsyncTask: Finished and throwing...
 1102 [5] InAsyncSafe: Caught InAsyncSafe: System.AggregateException: One or more errors occurred. (_boom: AsyncTask_) ---> System.Exception: _boom: AsyncTask_
   at AsyncExamples.AsyncTask() in C:\vsprojects\AsyncExamples\AsyncExamples.cs:line 19
   --- End of inner exception stack trace ---
---> (Inner Exception #0) System.Exception: _boom: AsyncTask_
   at AsyncExamples.AsyncTask() in C:\vsprojects\AsyncExamples\AsyncExamples.cs:line 19<---
-------------------------------------------------------------------
AsyncExamples.AsyncTaskWithOwnTryCatch();
-------------------------------------------------------------------
    0 [1] Main: Start
    2 [1] AsyncTaskWithOwnTryCatch: Starting...
   11 [1] Main: Press any key...
 1014 [4] AsyncTaskWithOwnTryCatch: Finished and throwing...
 1098 [4] AsyncTaskWithOwnTryCatch: Caught exception: System.Exception: _boom: AsyncTaskWithOwnTryCatch_
   at AsyncExamples.AsyncTaskWithOwnTryCatch() in C:\vsprojects\AsyncExamples\AsyncExamples.cs:line 36
-------------------------------------------------------------------
AsyncExamples.AsyncTaskWithOwnTryCatchNested();
-------------------------------------------------------------------
    0 [1] Main: Start
    4 [1] AsyncTaskWithOwnTryCatchNested: Starting...
    5 [1] NestedAsyncCall: Starting...
   12 [1] Main: Press any key...
 1016 [4] NestedAsyncCall: Finished and throwing...
 1112 [4] AsyncTaskWithOwnTryCatchNested: Caught exception: System.Exception: _boom: NestedAsyncCall_
   at AsyncExamples.NestedAsyncCall() in C:\vsprojects\AsyncExamples\AsyncExamples.cs:line 64
   at AsyncExamples.AsyncTaskWithOwnTryCatchNested() in C:\vsprojects\AsyncExamples\AsyncExamples.cs:line 49
-------------------------------------------------------------------
AsyncExamples.ExecutionOrderFirst().InAsyncSafe();
-------------------------------------------------------------------
    2 [1] Main: Start
   19 [1] ExecutionOrderFirst: Starting
   34 [1] Main: Press any key...
 1037 [4] ExecutionOrderFirst: About to await next method
 1040 [4] ExecutionOrderSecond: Starting
 2044 [4] ExecutionOrderSecond: About to await next method
 2047 [4] ExecutionOrderThird: Starting
 3051 [4] ExecutionOrderThird: Finished
 3051 [4] ExecutionOrderSecond: Finished
 3051 [4] ExecutionOrderFirst: Finished
-------------------------------------------------------------------
AsyncExamples.ThrowableComputationFlowAsync(new Exception("do not suppress"), ex => ex.Message == "suppress").InAsyncSafe();
-------------------------------------------------------------------
    0 [1] Main: Start
    4 [1] ThrowableComputationFlowAsync: Starting
    6 [1] ThrowableComputationAsync: Starting
   16 [1] Main: Press any key...
 1013 [4] ThrowableComputationAsync: Throwing
 1050 [4] InAsyncSafe: Caught InAsyncSafe: System.AggregateException: One or more errors occurred. (do not suppress) ---> System.Exception: do not suppress
   at AsyncExamples.ThrowableComputationAsync(Exception exceptionToThrow) in C:\vsprojects\AsyncExamples\AsyncExamples.cs:line 132
   at AsyncExamples.SuppressErrors[T](Task`1 task, Func`2 suppressPredicate) in C:\vsprojects\AsyncExamples\AsyncExamples.cs:line 97
   at AsyncExamples.ThrowableComputationFlowAsync(Exception exceptionToThrow, Func`2 suppressPredicate) in C:\vsprojects\AsyncExamples\AsyncExamples.cs:line 116
   --- End of inner exception stack trace ---
---> (Inner Exception #0) System.Exception: do not suppress
   at AsyncExamples.ThrowableComputationAsync(Exception exceptionToThrow) in C:\vsprojects\AsyncExamples\AsyncExamples.cs:line 132
   at AsyncExamples.SuppressErrors[T](Task`1 task, Func`2 suppressPredicate) in C:\vsprojects\AsyncExamples\AsyncExamples.cs:line 97
   at AsyncExamples.ThrowableComputationFlowAsync(Exception exceptionToThrow, Func`2 suppressPredicate) in C:\vsprojects\AsyncExamples\AsyncExamples.cs:line 116<---
-------------------------------------------------------------------
AsyncExamples.ThrowableComputationFlowAsync(new Exception("suppress"), ex => ex.Message == "suppress").InAsyncSafe();
-------------------------------------------------------------------
    0 [1] Main: Start
    4 [1] ThrowableComputationFlowAsync: Starting
    5 [1] ThrowableComputationAsync: Starting
   15 [1] Main: Press any key...
 1013 [4] ThrowableComputationAsync: Throwing
 1072 [4] SuppressErrors: Suppressed exception System.Exception: suppress
   at AsyncExamples.ThrowableComputationAsync(Exception exceptionToThrow) in C:\vsprojects\AsyncExamples\AsyncExamples.cs:line 132
   at AsyncExamples.SuppressErrors[T](Task`1 task, Func`2 suppressPredicate) in C:\vsprojects\AsyncExamples\AsyncExamples.cs:line 97
 1072 [4] ThrowableComputationFlowAsync: Got result: 0
-------------------------------------------------------------------
AsyncExamples.ThrowableComputationFlowWithDefaultSuppressAsync(new Exception("do not suppress")).InAsyncSafe();
-------------------------------------------------------------------
    0 [1] Main: Start
    5 [1] ThrowableComputationFlowWithDefaultSuppressAsync: Starting
    6 [1] ThrowableComputationAsync: Starting
   17 [1] Main: Press any key...
 1013 [4] ThrowableComputationAsync: Throwing
 1048 [4] InAsyncSafe: Caught InAsyncSafe: System.AggregateException: One or more errors occurred. (do not suppress) ---> System.Exception: do not suppress
   at AsyncExamples.ThrowableComputationAsync(Exception exceptionToThrow) in C:\vsprojects\AsyncExamples\AsyncExamples.cs:line 144
   at AsyncExamples.SuppressErrors[T](Task`1 task, Func`2 suppressPredicate) in C:\vsprojects\AsyncExamples\AsyncExamples.cs:line 97
   at AsyncExamples.ThrowableComputationFlowWithDefaultSuppressAsync(Exception exceptionToThrow) in C:\vsprojects\AsyncExamples\AsyncExamples.cs:line 128
   --- End of inner exception stack trace ---
---> (Inner Exception #0) System.Exception: do not suppress
   at AsyncExamples.ThrowableComputationAsync(Exception exceptionToThrow) in C:\vsprojects\AsyncExamples\AsyncExamples.cs:line 144
   at AsyncExamples.SuppressErrors[T](Task`1 task, Func`2 suppressPredicate) in C:\vsprojects\AsyncExamples\AsyncExamples.cs:line 97
   at AsyncExamples.ThrowableComputationFlowWithDefaultSuppressAsync(Exception exceptionToThrow) in C:\vsprojects\AsyncExamples\AsyncExamples.cs:line 128<---
-------------------------------------------------------------------
AsyncExamples.ThrowableComputationFlowWithDefaultSuppressAsync(new Exception("suppress")).InAsyncSafe();
-------------------------------------------------------------------
    0 [1] Main: Start
    4 [1] ThrowableComputationFlowWithDefaultSuppressAsync: Starting
    5 [1] ThrowableComputationAsync: Starting
   17 [1] Main: Press any key...
 1013 [4] ThrowableComputationAsync: Throwing
 1049 [4] SuppressErrors: Suppressed exception System.Exception: suppress
   at AsyncExamples.ThrowableComputationAsync(Exception exceptionToThrow) in C:\vsprojects\AsyncExamples\AsyncExamples.cs:line 144
   at AsyncExamples.SuppressErrors[T](Task`1 task, Func`2 suppressPredicate) in C:\vsprojects\AsyncExamples\AsyncExamples.cs:line 97
 1049 [4] ThrowableComputationFlowWithDefaultSuppressAsync: Got result: 0
